Workbook
Name dFrom: Dashboard!$B$6
Name dHost: Dashboard!$AE$4
Name dTo: Dashboard!$D$6
Name HostRoster: 'Cleaned Data'!$Z$9:$Z$13

Sheet README
B1: LIVE COMMERCE SALES PERFORMANCE ANALYSIS
A2: Excel-Based GMV Tracking, Host Performance Reporting, and Sales Analytics
B3: Prepared by John Paulo Lumagbas | Self-directed portfolio project | Entry-level Data Analyst portfolio
B6: ⚠ Portfolio project using synthetic data. Figures, hosts, and business information are fictional and do not represent any actual company's performance.
B8: PROJECT PURPOSE & BUSINESS SCENARIO
B9: Purpose: demonstrate practical, entry-level data analysis in Excel — organising business data, validating it, building accurate formulas, summarising results, and communicating insights through a dashboard. The project is inspired by my experience recording livestream sales and GMV in spreadsheets as a Livestream Assistant; it is a self-directed portfolio piece, not work product from a data analyst role.
B10: Scenario: “Sample Live Commerce Store” (fictional) runs livestream shopping sessions with five fictional hosts. Management wants to know how much GMV the sessions generate, how performance changes week to week, which hosts contribute and which are most efficient, and when sessions perform best. The dataset covers 374 synthetic sessions across 13 full weeks (Mon 02 Jun 2025 – Sun 31 Aug 2025).
B11: Tools & techniques: Microsoft Excel — Excel Tables and structured references, SUMIFS / COUNTIFS / INDEX-MATCH / RANK / CORREL / SLOPE, date and time functions, named ranges, data validation, conditional formatting, formula-driven dashboard filters, native charts. No macros, no dynamic-array functions and no add-ins are required (works in Excel 2010 or later).
B12: WORKBOOK GUIDE (click a sheet name)
B13: Raw Data | C13: Source layer: 374 synthetic session records in Excel Table tblRaw. Values only; no calculations.
B14: Cleaned Data | C14: Formula layer tblClean: standardises each raw row, derives duration, GMV per hour, week, month, slot; runs live data-quality checks and sets an Include flag.
B15: Daily Sales | C15: 91-day report: sessions, hours, GMV, items, GMV per hour, 7-day average, reconciliation to raw data, chart.
B16: Weekly Summary | C16: 13 weekly rows with week-over-week change and %, reconciliation, weekly GMV chart.
B17: Host Performance | C17: Host scorecard, documented ranking rule, host × time-slot efficiency table, weekly GMV heat-map by host.
B18: Dashboard | C18: Executive view: six KPI cards, five charts, date-range and host filters (yellow cells).
B19: Insights | C19: Eight calculated findings with why-it-matters and next steps, plus supporting tables.
B20: Flow: Raw Data → Cleaned Data (tblClean) → Daily / Weekly / Host summaries → Dashboard → Insights. Every summary reads from tblClean and counts only rows with Include = 1; each summary sheet reconciles back to Raw Data.
B21: HOW TO USE THE DASHBOARD
B22: Change the yellow cells on the Dashboard: From Date, To Date (dates between 02-Jun-2025 and 31-Aug-2025) and Host (dropdown). KPI cards, the daily trend and the weekly trend recalculate for the selected dates and host. The three host-comparison charts respond to the date range only, so all hosts stay visible for comparison. Limitation: this uses formula-driven filters rather than PivotTable slicers, so it works in any desktop Excel version without setup; weeks at the edge of a custom date range show partial totals, and charts skip days/weeks outside the range (helper cells use NA() placeholders by design).
B23: METRIC DEFINITIONS
B24: GMV | C24: Gross Merchandise Value: total value of goods sold through livestream sessions (here, “Attributed GMV”, in Philippine pesos). GMV is NOT net revenue, profit or cash received; returns, cancellations, discounts, fees and costs are not modelled.
B25: Items Sold | C25: Total units sold in a session (sum of item quantities).
B26: Livestream Duration | C26: Hours on air = (End Time − Start Time) × 24, using MOD(…,1) so sessions that cross midnight are handled.
B27: GMV per Hour | C27: Total GMV ÷ total livestream hours. Overall and per-host rates are weighted (sum ÷ sum), never an average of session-level rates, because session lengths differ.
B28: Views | C28: Number of livestream views recorded for a session.
B29: GMV per 1K Views | C29: Total GMV ÷ total views × 1,000. A sales-yield measure per 1,000 views; it is not a conversion rate.
B30: Average Order Value | C30: NOT calculated: the dataset has no order count, so AOV cannot be derived honestly.
B31: Conversion Rate | C31: NOT calculated: the dataset has no clicks, visitors or orders to use as a denominator.
B32: Weekly GMV | C32: GMV summed over a Monday–Sunday reporting week (Week Start = date − WEEKDAY(date,2) + 1).
B33: WoW Change / % | C33: Current-week GMV − previous-week GMV; % = change ÷ previous week. Shown as n/a for week 1 or when the prior week is zero/missing.
B34: Host Performance | C34: Host results measured together: total GMV (contribution), GMV per hour (efficiency), average GMV and items per session, share of GMV, and Efficiency Index (share of GMV ÷ share of hours).
B35: Time Slot | C35: Based on session start time: Morning 06–12h, Afternoon 12–16h, Early Evening 16–19h, Prime Time 19–22h, Late Night 22–06h.
B36: DATA QUALITY & DESIGN DECISIONS
B37: • Single dataset: all months live in one table instead of separate monthly tabs, so every report reads the same source.
B38: • Typed-in inputs only on Raw Data; all totals, rates and rankings are formulas (no hardcoded totals). Reports reconcile to Raw Data and show ✔ Reconciled / PASS checks.
B39: • Cleaning layer handles issues common in manual trackers: text-formatted numbers, times typed as text, inconsistent host spelling/spacing, duplicate IDs, negative or missing values, impossible durations. The synthetic sample is clean, so all checks currently read PASS; the checks are live and would flag problems in newly pasted data.
B40: • Excel functions only (no Google-Sheets-only formulas, no spill arrays). Data validation on Raw Data restricts GMV/items/views/followers to non-negative values and hosts to the roster.
B41: • Power Query alternative: Data → From Table/Range on tblRaw → Transform: trim/capitalise Host Name; set Date, Time and number types; add custom columns Duration = Duration.TotalHours(End − Start) with +1 day when End < Start, Week Start = Date.StartOfWeek(Date, Day.Monday); remove duplicates on Session ID; filter negatives → Close & Load to a table. The formula version above is used so the workbook works without any setup.
B42: DATA DICTIONARY
B43: Sheet | C43: Field | D43: Type | E43: Description | F43: How it is derived
...

Sheet Raw Data
A1: RAW DATA | Synthetic Livestream Session Log
A2: Source layer: values as recorded, one row per livestream session. All figures are fictional (synthetic). Add new sessions directly beneath the last row; the table expands automatically.
A4: Session ID | B4: Date | C4: Host Name | D4: Start Time | E4: End Time | F4: Attributed GMV PHP | G4: Items Sold | H4: Livestream Views | I4: New Followers
A5: LS-0001 | B5: 45810 | C5: Carlo Mendoza | D5: 0.54166667 | E5: 0.625 | F5: 32102 | G5: 85 | H5: 125767 | I5: 748
A6: LS-0002 | B6: 45810 | C6: Bianca Reyes | D6: 0.66666667 | E6: 0.79166667 | F6: 14260 | G6: 44 | H6: 53670 | I6: 396
A7: LS-0003 | B7: 45810 | C7: Aira Valdez | D7: 0.79166667 | E7: 0.89583333 | F7: 39064 | G7: 105 | H7: 121105 | I7: 1392
A8: LS-0004 | B8: 45811 | C8: Carlo Mendoza | D8: 0.41666667 | E8: 0.5 | F8: 11178 | G8: 27 | H8: 44877 | I8: 381
A9: LS-0005 | B9: 45811 | C9: Bianca Reyes | D9: 0.54166667 | E9: 0.64583333 | F9: 19147 | G9: 56 | H9: 64713 | I9: 629
A10: LS-0006 | B10: 45811 | C10: Carlo Mendoza | D10: 0.66666667 | E10: 0.77083333 | F10: 24963 | G10: 78 | H10: 77927 | I10: 344
A11: LS-0007 | B11: 45811 | C11: Aira Valdez | D11: 0.79166667 | E11: 0.89583333 | F11: 82257 | G11: 243 | H11: 216966 | I11: 1728
A12: LS-0008 | B12: 45811 | C12: Aira Valdez | D12: 0.91666667 | E12: 0.020833333 | F12: 39674 | G12: 119 | H12: 102019 | I12: 825
A13: LS-0009 | B13: 45812 | C13: Carlo Mendoza | D13: 0.66666667 | E13: 0.79166667 | F13: 25112 | G13: 73 | H13: 77728 | I13: 552
A14: LS-0010 | B14: 45812 | C14: Bianca Reyes | D14: 0.79166667 | E14: 0.89583333 | F14: 8207 | G14: 22 | H14: 27621 | I14: 298
A15: LS-0011 | B15: 45812 | C15: Dani Villanueva | D15: 0.91666667 | E15: 0.041666667 | F15: 26243 | G15: 77 | H15: 58338 | I15: 332
A16: LS-0012 | B16: 45813 | C16: Bianca Reyes | D16: 0.54166667 | E16: 0.625 | F16: 6069 | G16: 17 | H16: 20285 | I16: 262
... A378: LS-0374 | B378: 45900 | C378: Carlo Mendoza | D378: 0.91666667 | E378: 0.020833333 | F378: 51021 | G378: 139 | H378: 216876 | I378: 1414

Sheet Cleaned Data
A1: CLEANED DATA & CALCULATIONS | Formula-Driven Transformation Layer
A2: Each row links to the same row on 'Raw Data' and standardizes, derives and validates it. Every summary sheet reads from this table (tblClean), counting only rows where Include = 1.
A3: DATA QUALITY CHECKS (live formulas — all should read PASS)
A4: Raw rows vs cleaned rows | B4: Missing or non-numeric values | C4: Duplicate Session IDs | D4: Negative GMV / items / views / followers | E4: Invalid durations (≤0h or >12h) | F4: Host names not on roster | G4: Rows included in analysis | H4: GMV: raw minus included (PHP) | I4: Items: raw minus included
A5: =ROWS(tblRaw[Session ID]) -> 374 | B5: =SUM(tblClean[Missing Flag]) -> 0 | C5: =SUM(tblClean[Duplicate Flag]) -> 0 | D5: =SUM(tblClean[Negative Flag]) -> 0 | E5: =SUM(tblClean[Duration Flag]) -> 0 | F5: =SUM(tblClean[Host Flag]) -> 0 | G5: =SUM(tblClean[Include]) -> 374 | H5: =SUM(tblRaw[Attributed GMV PHP])-SUMIFS(tblClean[Attributed GMV PHP],tblClean[Include],1) -> 0 | I5: =SUM(tblRaw[Items Sold])-SUMIFS(tblClean[Items Sold],tblClean[Include],1) -> 0
A6: =IF(A5=ROWS(tblClean[Session ID]),"PASS","REVIEW") -> PASS | B6: =IF(B5=0,"PASS","REVIEW") -> PASS | C6: =IF(C5=0,"PASS","REVIEW") -> PASS | D6: =IF(D5=0,"PASS","REVIEW") -> PASS | E6: =IF(E5=0,"PASS","REVIEW") -> PASS | F6: =IF(F5=0,"PASS","REVIEW") -> PASS | G6: =IF(G5=ROWS(tblRaw[Session ID]),"PASS","REVIEW") -> PASS | H6: =IF(ROUND(H5,2)=0,"PASS","REVIEW") -> PASS | I6: =IF(I5=0,"PASS","REVIEW") -> PASS
A7: Rule: a row counts toward analysis only if none of the five flag columns (S–W) equals 1. If duplicate IDs exist, every row sharing the ID is held out for review.
A8: Session ID | B8: Date | C8: Host Name | D8: Start Time | E8: End Time | F8: Attributed GMV PHP | G8: Items Sold | H8: Livestream Views | I8: New Followers | J8: Duration Hours | K8: GMV per Hour | L8: Month | M8: Week Start | N8: Week Number | O8: Day of Week | P8: Day Type | Q8: Time Slot | R8: Duration Band | S8: Missing Flag | T8: Duplicate Flag | U8: Negative Flag | V8: Duration Flag | W8: Host Flag | X8: Include | Z8: Host Roster
A9: =TRIM('Raw Data'!A5) -> LS-0001 | B9: =IF(ISNUMBER('Raw Data'!B5),INT('Raw Data'!B5),IFERROR(DATEVALUE('Raw Data'!B5),"")) -> 45810 | C9: =PROPER(TRIM('Raw Data'!C5)) -> Carlo Mendoza | D9: =IF(ISNUMBER('Raw Data'!D5),MOD('Raw Data'!D5,1),IFERROR(TIMEVALUE('Raw Data'!D5),"")) -> 0.54166667 | E9: =IF(ISNUMBER('Raw Data'!E5),MOD('Raw Data'!E5,1),IFERROR(TIMEVALUE('Raw Data'!E5),"")) -> 0.625 | F9: =IF(ISNUMBER('Raw Data'!F5),'Raw Data'!F5,IFERROR(VALUE(SUBSTITUTE('Raw Data'!F5,",","")),"")) -> 32102 | G9: =IF(ISNUMBER('Raw Data'!G5),'Raw Data'!G5,IFERROR(VALUE(SUBSTITUTE('Raw Data'!G5,",","")),"")) -> 85 | H9: =IF(ISNUMBER('Raw Data'!H5),'Raw Data'!H5,IFERROR(VALUE(SUBSTITUTE('Raw Data'!H5,",","")),"")) -> 125767 | I9: =IF(ISNUMBER('Raw Data'!I5),'Raw Data'!I5,IFERROR(VALUE(SUBSTITUTE('Raw Data'!I5,",","")),"")) -> 748 | J9: =IF(AND(ISNUMBER(tblClean[[#This Row],[Start Time]]),ISNUMBER(tblClean[[#This Row],[End Time]])),ROUND(MOD(tblClean[[#This Row],[End Time]]-tblClean[[#This Row],[Start Time]],1)*24,2),"") -> 2 | K9: =IF(AND(ISNUMBER(tblClean[[#This Row],[Duration Hours]]),ISNUMBER(tblClean[[#This Row],[Attributed GMV PHP]])),IF(tblClean[[#This Row],[Duration Hours]]>0,tblClean[[#This Row],[Attributed GMV PHP]]/tblClean[[#This Row],[Duration Hours]],""),"") -> 16051 | L9: =IF(ISNUMBER(tblClean[[#This Row],[Date]]),DATE(YEAR(tblClean[[#This Row],[Date]]),MONTH(tblClean[[#This Row],[Date]]),1),"") -> 45809 | M9: =IF(ISNUMBER(tblClean[[#This Row],[Date]]),tblClean[[#This Row],[Date]]-WEEKDAY(tblClean[[#This Row],[Date]],2)+1,"") -> 45810 | N9: =IF(ISNUMBER(tblClean[[#This Row],[Week Start]]),(tblClean[[#This Row],[Week Start]]-MIN(tblClean[Week Start]))/7+1,"") -> 1 | O9: =IF(ISNUMBER(tblClean[[#This Row],[Date]]),CHOOSE(WEEKDAY(tblClean[[#This Row],[Date]],2),"Mon","Tue","Wed","Thu","Fri","Sat","Sun"),"") -> Mon | P9: =IF(ISNUMBER(tblClean[[#This Row],[Date]]),IF(WEEKDAY(tblClean[[#This Row],[Date]],2)>=6,"Weekend","Weekday"),"") -> Weekday | Q9: =IF(ISNUMBER(tblClean[[#This Row],[Start Time]]),IF(tblClean[[#This Row],[Start Time]]<TIME(6,0,0),"Late Night",IF(tblClean[[#This Row],[Start Time]]<TIME(12,0,0),"Morning",IF(tblClean[[#This Row],[Start Time]]<TIME(16,0,0),"Afternoon",IF(tblClean[[#This Row],[Start Time]]<TIME(19,0,0),"Early Evening",IF(tblClean[[#This Row],[Start Time]]<TIME(22,0,0),"Prime Time","Late Night"))))),"") -> Afternoon | R9: =IF(ISNUMBER(tblClean[[#This Row],[Duration Hours]]),IF(tblClean[[#This Row],[Duration Hours]]<2,"Short (under 2h)",IF(tblClean[[#This Row],[Duration Hours]]<3,"Standard (2h to under 3h)","Long (3h or more)")),"") -> Standard (2h to under 3h) | S9: =IF(OR(NOT(ISNUMBER(tblClean[[#This Row],[Date]])),NOT(ISNUMBER(tblClean[[#This Row],[Start Time]])),NOT(ISNUMBER(tblClean[[#This Row],[End Time]])),NOT(ISNUMBER(tblClean[[#This Row],[Attributed GMV PHP]])),NOT(ISNUMBER(tblClean[[#This Row],[Items Sold]])),NOT(ISNUMBER(tblClean[[#This Row],[Livestream Views]])),NOT(ISNUMBER(tblClean[[#This Row],[New Followers]])),tblClean[[#This Row],[Host Name]]="",tblClean[[#This Row],[Session ID]]=""),1,0) -> 0 | T9: =IF(COUNTIF(tblClean[Session ID],tblClean[[#This Row],[Session ID]])>1,1,0) -> 0 | U9: =IF(OR(N(tblClean[[#This Row],[Attributed GMV PHP]])<0,N(tblClean[[#This Row],[Items Sold]])<0,N(tblClean[[#This Row],[Livestream Views]])<0,N(tblClean[[#This Row],[New Followers]])<0),1,0) -> 0 | V9: =IF(ISNUMBER(tblClean[[#This Row],[Duration Hours]]),IF(OR(tblClean[[#This Row],[Duration Hours]]<=0,tblClean[[#This Row],[Duration Hours]]>12),1,0),1) -> 0 | W9: =IF(COUNTIF(HostRoster,tblClean[[#This Row],[Host Name]])=0,1,0) -> 0 | X9: =IF(tblClean[[#This Row],[Missing Flag]]+tblClean[[#This Row],[Duplicate Flag]]+tblClean[[#This Row],[Negative Flag]]+tblClean[[#This Row],[Duration Flag]]+tblClean[[#This Row],[Host Flag]]=0,1,0) -> 1 | Z9: Aira Valdez
A10: =TRIM('Raw Data'!A6) -> LS-0002 | B10: =IF(ISNUMBER('Raw Data'!B6),INT('Raw Data'!B6),IFERROR(DATEVALUE('Raw Data'!B6),"")) -> 45810 | C10: =PROPER(TRIM('Raw Data'!C6)) -> Bianca Reyes | D10: =IF(ISNUMBER('Raw Data'!D6),MOD('Raw Data'!D6,1),IFERROR(TIMEVALUE('Raw Data'!D6),"")) -> 0.66666667 | E10: =IF(ISNUMBER('Raw Data'!E6),MOD('Raw Data'!E6,1),IFERROR(TIMEVALUE('Raw Data'!E6),"")) -> 0.79166667 | F10: =IF(ISNUMBER('Raw Data'!F6),'Raw Data'!F6,IFERROR(VALUE(SUBSTITUTE('Raw Data'!F6,",","")),"")) -> 14260 | G10: =IF(ISNUMBER('Raw Data'!G6),'Raw Data'!G6,IFERROR(VALUE(SUBSTITUTE('Raw Data'!G6,",","")),"")) -> 44 | H10: =IF(ISNUMBER('Raw Data'!H6),'Raw Data'!H6,IFERROR(VALUE(SUBSTITUTE('Raw Data'!H6,",","")),"")) -> 53670 | I10: =IF(ISNUMBER('Raw Data'!I6),'Raw Data'!I6,IFERROR(VALUE(SUBSTITUTE('Raw Data'!I6,",","")),"")) -> 396 | J10: =IF(AND(ISNUMBER(tblClean[[#This Row],[Start Time]]),ISNUMBER(tblClean[[#This Row],[End Time]])),ROUND(MOD(tblClean[[#This Row],[End Time]]-tblClean[[#This Row],[Start Time]],1)*24,2),"") -> 3 | K10: =IF(AND(ISNUMBER(tblClean[[#This Row],[Duration Hours]]),ISNUMBER(tblClean[[#This Row],[Attributed GMV PHP]])),IF(tblClean[[#This Row],[Duration Hours]]>0,tblClean[[#This Row],[Attributed GMV PHP]]/tblClean[[#This Row],[Duration Hours]],""),"") -> 4753.3333 | L10: =IF(ISNUMBER(tblClean[[#This Row],[Date]]),DATE(YEAR(tblClean[[#This Row],[Date]]),MONTH(tblClean[[#This Row],[Date]]),1),"") -> 45809 | M10: =IF(ISNUMBER(tblClean[[#This Row],[Date]]),tblClean[[#This Row],[Date]]-WEEKDAY(tblClean[[#This Row],[Date]],2)+1,"") -> 45810 | N10: =IF(ISNUMBER(tblClean[[#This Row],[Week Start]]),(tblClean[[#This Row],[Week Start]]-MIN(tblClean[Week Start]))/7+1,"") -> 1 | O10: =IF(ISNUMBER(tblClean[[#This Row],[Date]]),CHOOSE(WEEKDAY(tblClean[[#This Row],[Date]],2),"Mon","Tue","Wed","Thu","Fri","Sat","Sun"),"") -> Mon | P10: =IF(ISNUMBER(tblClean[[#This Row],[Date]]),IF(WEEKDAY(tblClean[[#This Row],[Date]],2)>=6,"Weekend","Weekday"),"") -> Weekday | Q10: =IF(ISNUMBER(tblClean[[#This Row],[Start Time]]),IF(tblClean[[#This Row],[Start Time]]<TIME(6,0,0),"Late Night",IF(tblClean[[#This Row],[Start Time]]<TIME(12,0,0),"Morning",IF(tblClean[[#This Row],[Start Time]]<TIME(16,0,0),"Afternoon",IF(tblClean[[#This Row],[Start Time]]<TIME(19,0,0),"Early Evening",IF(tblClean[[#This Row],[Start Time]]<TIME(22,0,0),"Prime Time","Late Night"))))),"") -> Early Evening | R10: =IF(ISNUMBER(tblClean[[#This Row],[Duration Hours]]),IF(tblClean[[#This Row],[Duration Hours]]<2,"Short (under 2h)",IF(tblClean[[#This Row],[Duration Hours]]<3,"Standard (2h to under 3h)","Long (3h or more)")),"") -> Long (3h or more) | S10: =IF(OR(NOT(ISNUMBER(tblClean[[#This Row],[Date]])),NOT(ISNUMBER(tblClean[[#This Row],[Start Time]])),NOT(ISNUMBER(tblClean[[#This Row],[End Time]])),NOT(ISNUMBER(tblClean[[#This Row],[Attributed GMV PHP]])),NOT(ISNUMBER(tblClean[[#This Row],[Items Sold]])),NOT(ISNUMBER(tblClean[[#This Row],[Livestream Views]])),NOT(ISNUMBER(tblClean[[#This Row],[New Followers]])),tblClean[[#This Row],[Host Name]]="",tblClean[[#This Row],[Session ID]]=""),1,0) -> 0 | T10: =IF(COUNTIF(tblClean[Session ID],tblClean[[#This Row],[Session ID]])>1,1,0) -> 0 | U10: =IF(OR(N(tblClean[[#This Row],[Attributed GMV PHP]])<0,N(tblClean[[#This Row],[Items Sold]])<0,N(tblClean[[#This Row],[Livestream Views]])<0,N(tblClean[[#This Row],[New Followers]])<0),1,0) -> 0 | V10: =IF(ISNUMBER(tblClean[[#This Row],[Duration Hours]]),IF(OR(tblClean[[#This Row],[Duration Hours]]<=0,tblClean[[#This Row],[Duration Hours]]>12),1,0),1) -> 0 | W10: =IF(COUNTIF(HostRoster,tblClean[[#This Row],[Host Name]])=0,1,0) -> 0 | X10: =IF(tblClean[[#This Row],[Missing Flag]]+tblClean[[#This Row],[Duplicate Flag]]+tblClean[[#This Row],[Negative Flag]]+tblClean[[#This Row],[Duration Flag]]+tblClean[[#This Row],[Host Flag]]=0,1,0) -> 1 | Z10: Bianca Reyes
A11: =TRIM('Raw Data'!A7) -> LS-0003 | B11: =IF(ISNUMBER('Raw Data'!B7),INT('Raw Data'!B7),IFERROR(DATEVALUE('Raw Data'!B7),"")) -> 45810 | C11: =PROPER(TRIM('Raw Data'!C7)) -> Aira Valdez | D11: =IF(ISNUMBER('Raw Data'!D7),MOD('Raw Data'!D7,1),IFERROR(TIMEVALUE('Raw Data'!D7),"")) -> 0.79166667 | E11: =IF(ISNUMBER('Raw Data'!E7),MOD('Raw Data'!E7,1),IFERROR(TIMEVALUE('Raw Data'!E7),"")) -> 0.89583333 | F11: =IF(ISNUMBER('Raw Data'!F7),'Raw Data'!F7,IFERROR(VALUE(SUBSTITUTE('Raw Data'!F7,",","")),"")) -> 39064 | G11: =IF(ISNUMBER('Raw Data'!G7),'Raw Data'!G7,IFERROR(VALUE(SUBSTITUTE('Raw Data'!G7,",","")),"")) -> 105 | H11: =IF(ISNUMBER('Raw Data'!H7),'Raw Data'!H7,IFERROR(VALUE(SUBSTITUTE('Raw Data'!H7,",","")),"")) -> 121105 | I11: =IF(ISNUMBER('Raw Data'!I7),'Raw Data'!I7,IFERROR(VALUE(SUBSTITUTE('Raw Data'!I7,",","")),"")) -> 1392 | J11: =IF(AND(ISNUMBER(tblClean[[#This Row],[Start Time]]),ISNUMBER(tblClean[[#This Row],[End Time]])),ROUND(MOD(tblClean[[#This Row],[End Time]]-tblClean[[#This Row],[Start Time]],1)*24,2),"") -> 2.5 | K11: =IF(AND(ISNUMBER(tblClean[[#This Row],[Duration Hours]]),ISNUMBER(tblClean[[#This Row],[Attributed GMV PHP]])),IF(tblClean[[#This Row],[Duration Hours]]>0,tblClean[[#This Row],[Attributed GMV PHP]]/tblClean[[#This Row],[Duration Hours]],""),"") -> 15625.6 | L11: =IF(ISNUMBER(tblClean[[#This Row],[Date]]),DATE(YEAR(tblClean[[#This Row],[Date]]),MONTH(tblClean[[#This Row],[Date]]),1),"") -> 45809 | M11: =IF(ISNUMBER(tblClean[[#This Row],[Date]]),tblClean[[#This Row],[Date]]-WEEKDAY(tblClean[[#This Row],[Date]],2)+1,"") -> 45810 | N11: =IF(ISNUMBER(tblClean[[#This Row],[Week Start]]),(tblClean[[#This Row],[Week Start]]-MIN(tblClean[Week Start]))/7+1,"") -> 1 | O11: =IF(ISNUMBER(tblClean[[#This Row],[Date]]),CHOOSE(WEEKDAY(tblClean[[#This Row],[Date]],2),"Mon","Tue","Wed","Thu","Fri","Sat","Sun"),"") -> Mon | P11: =IF(ISNUMBER(tblClean[[#This Row],[Date]]),IF(WEEKDAY(tblClean[[#This Row],[Date]],2)>=6,"Weekend","Weekday"),"") -> Weekday | Q11: =IF(ISNUMBER(tblClean[[#This Row],[Start Time]]),IF(tblClean[[#This Row],[Start Time]]<TIME(6,0,0),"Late Night",IF(tblClean[[#This Row],[Start Time]]<TIME(12,0,0),"Morning",IF(tblClean[[#This Row],[Start Time]]<TIME(16,0,0),"Afternoon",IF(tblClean[[#This Row],[Start Time]]<TIME(19,0,0),"Early Evening",IF(tblClean[[#This Row],[Start Time]]<TIME(22,0,0),"Prime Time","Late Night"))))),"") -> Prime Time | R11: =IF(ISNUMBER(tblClean[[#This Row],[Duration Hours]]),IF(tblClean[[#This Row],[Duration Hours]]<2,"Short (under 2h)",IF(tblClean[[#This Row],[Duration Hours]]<3,"Standard (2h to under 3h)","Long (3h or more)")),"") -> Standard (2h to under 3h) | S11: =IF(OR(NOT(ISNUMBER(tblClean[[#This Row],[Date]])),NOT(ISNUMBER(tblClean[[#This Row],[Start Time]])),NOT(ISNUMBER(tblClean[[#This Row],[End Time]])),NOT(ISNUMBER(tblClean[[#This Row],[Attributed GMV PHP]])),NOT(ISNUMBER(tblClean[[#This Row],[Items Sold]])),NOT(ISNUMBER(tblClean[[#This Row],[Livestream Views]])),NOT(ISNUMBER(tblClean[[#This Row],[New Followers]])),tblClean[[#This Row],[Host Name]]="",tblClean[[#This Row],[Session ID]]=""),1,0) -> 0 | T11: =IF(COUNTIF(tblClean[Session ID],tblClean[[#This Row],[Session ID]])>1,1,0) -> 0 | U11: =IF(OR(N(tblClean[[#This Row],[Attributed GMV PHP]])<0,N(tblClean[[#This Row],[Items Sold]])<0,N(tblClean[[#This Row],[Livestream Views]])<0,N(tblClean[[#This Row],[New Followers]])<0),1,0) -> 0 | V11: =IF(ISNUMBER(tblClean[[#This Row],[Duration Hours]]),IF(OR(tblClean[[#This Row],[Duration Hours]]<=0,tblClean[[#This Row],[Duration Hours]]>12),1,0),1) -> 0 | W11: =IF(COUNTIF(HostRoster,tblClean[[#This Row],[Host Name]])=0,1,0) -> 0 | X11: =IF(tblClean[[#This Row],[Missing Flag]]+tblClean[[#This Row],[Duplicate Flag]]+tblClean[[#This Row],[Negative Flag]]+tblClean[[#This Row],[Duration Flag]]+tblClean[[#This Row],[Host Flag]]=0,1,0) -> 1 | Z11: Carlo Mendoza
A12: =TRIM('Raw Data'!A8) -> LS-0004 | B12: =IF(ISNUMBER('Raw Data'!B8),INT('Raw Data'!B8),IFERROR(DATEVALUE('Raw Data'!B8),"")) -> 45811 | C12: =PROPER(TRIM('Raw Data'!C8)) -> Carlo Mendoza | D12: =IF(ISNUMBER('Raw Data'!D8),MOD('Raw Data'!D8,1),IFERROR(TIMEVALUE('Raw Data'!D8),"")) -> 0.41666667 | E12: =IF(ISNUMBER('Raw Data'!E8),MOD('Raw Data'!E8,1),IFERROR(TIMEVALUE('Raw Data'!E8),"")) -> 0.5 | F12: =IF(ISNUMBER('Raw Data'!F8),'Raw Data'!F8,IFERROR(VALUE(SUBSTITUTE('Raw Data'!F8,",","")),"")) -> 11178 | G12: =IF(ISNUMBER('Raw Data'!G8),'Raw Data'!G8,IFERROR(VALUE(SUBSTITUTE('Raw Data'!G8,",","")),"")) -> 27 | H12: =IF(ISNUMBER('Raw Data'!H8),'Raw Data'!H8,IFERROR(VALUE(SUBSTITUTE('Raw Data'!H8,",","")),"")) -> 44877 | I12: =IF(ISNUMBER('Raw Data'!I8),'Raw Data'!I8,IFERROR(VALUE(SUBSTITUTE('Raw Data'!I8,",","")),"")) -> 381 | J12: =IF(AND(ISNUMBER(tblClean[[#This Row],[Start Time]]),ISNUMBER(tblClean[[#This Row],[End Time]])),ROUND(MOD(tblClean[[#This Row],[End Time]]-tblClean[[#This Row],[Start Time]],1)*24,2),"") -> 2 | K12: =IF(AND(ISNUMBER(tblClean[[#This Row],[Duration Hours]]),ISNUMBER(tblClean[[#This Row],[Attributed GMV PHP]])),IF(tblClean[[#This Row],[Duration Hours]]>0,tblClean[[#This Row],[Attributed GMV PHP]]/tblClean[[#This Row],[Duration Hours]],""),"") -> 5589 | L12: =IF(ISNUMBER(tblClean[[#This Row],[Date]]),DATE(YEAR(tblClean[[#This Row],[Date]]),MONTH(tblClean[[#This Row],[Date]]),1),"") -> 45809 | M12: =IF(ISNUMBER(tblClean[[#This Row],[Date]]),tblClean[[#This Row],[Date]]-WEEKDAY(tblClean[[#This Row],[Date]],2)+1,"") -> 45810 | N12: =IF(ISNUMBER(tblClean[[#This Row],[Week Start]]),(tblClean[[#This Row],[Week Start]]-MIN(tblClean[Week Start]))/7+1,"") -> 1 | O12: =IF(ISNUMBER(tblClean[[#This Row],[Date]]),CHOOSE(WEEKDAY(tblClean[[#This Row],[Date]],2),"Mon","Tue","Wed","Thu","Fri","Sat","Sun"),"") -> Tue | P12: =IF(ISNUMBER(tblClean[[#This Row],[Date]]),IF(WEEKDAY(tblClean[[#This Row],[Date]],2)>=6,"Weekend","Weekday"),"") -> Weekday | Q12: =IF(ISNUMBER(tblClean[[#This Row],[Start Time]]),IF(tblClean[[#This Row],[Start Time]]<TIME(6,0,0),"Late Night",IF(tblClean[[#This Row],[Start Time]]<TIME(12,0,0),"Morning",IF(tblClean[[#This Row],[Start Time]]<TIME(16,0,0),"Afternoon",IF(tblClean[[#This Row],[Start Time]]<TIME(19,0,0),"Early Evening",IF(tblClean[[#This Row],[Start Time]]<TIME(22,0,0),"Prime Time","Late Night"))))),"") -> Morning | R12: =IF(ISNUMBER(tblClean[[#This Row],[Duration Hours]]),IF(tblClean[[#This Row],[Duration Hours]]<2,"Short (under 2h)",IF(tblClean[[#This Row],[Duration Hours]]<3,"Standard (2h to under 3h)","Long (3h or more)")),"") -> Standard (2h to under 3h) | S12: =IF(OR(NOT(ISNUMBER(tblClean[[#This Row],[Date]])),NOT(ISNUMBER(tblClean[[#This Row],[Start Time]])),NOT(ISNUMBER(tblClean[[#This Row],[End Time]])),NOT(ISNUMBER(tblClean[[#This Row],[Attributed GMV PHP]])),NOT(ISNUMBER(tblClean[[#This Row],[Items Sold]])),NOT(ISNUMBER(tblClean[[#This Row],[Livestream Views]])),NOT(ISNUMBER(tblClean[[#This Row],[New Followers]])),tblClean[[#This Row],[Host Name]]="",tblClean[[#This Row],[Session ID]]=""),1,0) -> 0 | T12: =IF(COUNTIF(tblClean[Session ID],tblClean[[#This Row],[Session ID]])>1,1,0) -> 0 | U12: =IF(OR(N(tblClean[[#This Row],[Attributed GMV PHP]])<0,N(tblClean[[#This Row],[Items Sold]])<0,N(tblClean[[#This Row],[Livestream Views]])<0,N(tblClean[[#This Row],[New Followers]])<0),1,0) -> 0 | V12: =IF(ISNUMBER(tblClean[[#This Row],[Duration Hours]]),IF(OR(tblClean[[#This Row],[Duration Hours]]<=0,tblClean[[#This Row],[Duration Hours]]>12),1,0),1) -> 0 | W12: =IF(COUNTIF(HostRoster,tblClean[[#This Row],[Host Name]])=0,1,0) -> 0 | X12: =IF(tblClean[[#This Row],[Missing Flag]]+tblClean[[#This Row],[Duplicate Flag]]+tblClean[[#This Row],[Negative Flag]]+tblClean[[#This Row],[Duration Flag]]+tblClean[[#This Row],[Host Flag]]=0,1,0) -> 1 | Z12: Dani Villanueva
A13: =TRIM('Raw Data'!A9) -> LS-0005 | B13: =IF(ISNUMBER('Raw Data'!B9),INT('Raw Data'!B9),IFERROR(DATEVALUE('Raw Data'!B9),"")) -> 45811 | C13: =PROPER(TRIM('Raw Data'!C9)) -> Bianca Reyes | D13: =IF(ISNUMBER('Raw Data'!D9),MOD('Raw Data'!D9,1),IFERROR(TIMEVALUE('Raw Data'!D9),"")) -> 0.54166667 | E13: =IF(ISNUMBER('Raw Data'!E9),MOD('Raw Data'!E9,1),IFERROR(TIMEVALUE('Raw Data'!E9),"")) -> 0.64583333 | F13: =IF(ISNUMBER('Raw Data'!F9),'Raw Data'!F9,IFERROR(VALUE(SUBSTITUTE('Raw Data'!F9,",","")),"")) -> 19147 | G13: =IF(ISNUMBER('Raw Data'!G9),'Raw Data'!G9,IFERROR(VALUE(SUBSTITUTE('Raw Data'!G9,",","")),"")) -> 56 | H13: =IF(ISNUMBER('Raw Data'!H9),'Raw Data'!H9,IFERROR(VALUE(SUBSTITUTE('Raw Data'!H9,",","")),"")) -> 64713 | I13: =IF(ISNUMBER('Raw Data'!I9),'Raw Data'!I9,IFERROR(VALUE(SUBSTITUTE('Raw Data'!I9,",","")),"")) -> 629 | J13: =IF(AND(ISNUMBER(tblClean[[#This Row],[Start Time]]),ISNUMBER(tblClean[[#This Row],[End Time]])),ROUND(MOD(tblClean[[#This Row],[End Time]]-tblClean[[#This Row],[Start Time]],1)*24,2),"") -> 2.5 | K13: =IF(AND(ISNUMBER(tblClean[[#This Row],[Duration Hours]]),ISNUMBER(tblClean[[#This Row],[Attributed GMV PHP]])),IF(tblClean[[#This Row],[Duration Hours]]>0,tblClean[[#This Row],[Attributed GMV PHP]]/tblClean[[#This Row],[Duration Hours]],""),"") -> 7658.8 | L13: =IF(ISNUMBER(tblClean[[#This Row],[Date]]),DATE(YEAR(tblClean[[#This Row],[Date]]),MONTH(tblClean[[#This Row],[Date]]),1),"") -> 45809 | M13: =IF(ISNUMBER(tblClean[[#This Row],[Date]]),tblClean[[#This Row],[Date]]-WEEKDAY(tblClean[[#This Row],[Date]],2)+1,"") -> 45810 | N13: =IF(ISNUMBER(tblClean[[#This Row],[Week Start]]),(tblClean[[#This Row],[Week Start]]-MIN(tblClean[Week Start]))/7+1,"") -> 1 | O13: =IF(ISNUMBER(tblClean[[#This Row],[Date]]),CHOOSE(WEEKDAY(tblClean[[#This Row],[Date]],2),"Mon","Tue","Wed","Thu","Fri","Sat","Sun"),"") -> Tue | P13: =IF(ISNUMBER(tblClean[[#This Row],[Date]]),IF(WEEKDAY(tblClean[[#This Row],[Date]],2)>=6,"Weekend","Weekday"),"") -> Weekday | Q13: =IF(ISNUMBER(tblClean[[#This Row],[Start Time]]),IF(tblClean[[#This Row],[Start Time]]<TIME(6,0,0),"Late Night",IF(tblClean[[#This Row],[Start Time]]<TIME(12,0,0),"Morning",IF(tblClean[[#This Row],[Start Time]]<TIME(16,0,0),"Afternoon",IF(tblClean[[#This Row],[Start Time]]<TIME(19,0,0),"Early Evening",IF(tblClean[[#This Row],[Start Time]]<TIME(22,0,0),"Prime Time","Late Night"))))),"") -> Afternoon | R13: =IF(ISNUMBER(tblClean[[#This Row],[Duration Hours]]),IF(tblClean[[#This Row],[Duration Hours]]<2,"Short (under 2h)",IF(tblClean[[#This Row],[Duration Hours]]<3,"Standard (2h to under 3h)","Long (3h or more)")),"") -> Standard (2h to under 3h) | S13: =IF(OR(NOT(ISNUMBER(tblClean[[#This Row],[Date]])),NOT(ISNUMBER(tblClean[[#This Row],[Start Time]])),NOT(ISNUMBER(tblClean[[#This Row],[End Time]])),NOT(ISNUMBER(tblClean[[#This Row],[Attributed GMV PHP]])),NOT(ISNUMBER(tblClean[[#This Row],[Items Sold]])),NOT(ISNUMBER(tblClean[[#This Row],[Livestream Views]])),NOT(ISNUMBER(tblClean[[#This Row],[New Followers]])),tblClean[[#This Row],[Host Name]]="",tblClean[[#This Row],[Session ID]]=""),1,0) -> 0 | T13: =IF(COUNTIF(tblClean[Session ID],tblClean[[#This Row],[Session ID]])>1,1,0) -> 0 | U13: =IF(OR(N(tblClean[[#This Row],[Attributed GMV PHP]])<0,N(tblClean[[#This Row],[Items Sold]])<0,N(tblClean[[#This Row],[Livestream Views]])<0,N(tblClean[[#This Row],[New Followers]])<0),1,0) -> 0 | V13: =IF(ISNUMBER(tblClean[[#This Row],[Duration Hours]]),IF(OR(tblClean[[#This Row],[Duration Hours]]<=0,tblClean[[#This Row],[Duration Hours]]>12),1,0),1) -> 0 | W13: =IF(COUNTIF(HostRoster,tblClean[[#This Row],[Host Name]])=0,1,0) -> 0 | X13: =IF(tblClean[[#This Row],[Missing Flag]]+tblClean[[#This Row],[Duplicate Flag]]+tblClean[[#This Row],[Negative Flag]]+tblClean[[#This Row],[Duration Flag]]+tblClean[[#This Row],[Host Flag]]=0,1,0) -> 1 | Z13: Elise Navarro
A14: =TRIM('Raw Data'!A10) -> LS-0006 | B14: =IF(ISNUMBER('Raw Data'!B10),INT('Raw Data'!B10),IFERROR(DATEVALUE('Raw Data'!B10),"")) -> 45811 | C14: =PROPER(TRIM('Raw Data'!C10)) -> Carlo Mendoza | D14: =IF(ISNUMBER('Raw Data'!D10),MOD('Raw Data'!D10,1),IFERROR(TIMEVALUE('Raw Data'!D10),"")) -> 0.66666667 | E14: =IF(ISNUMBER('Raw Data'!E10),MOD('Raw Data'!E10,1),IFERROR(TIMEVALUE('Raw Data'!E10),"")) -> 0.77083333 | F14: =IF(ISNUMBER('Raw Data'!F10),'Raw Data'!F10,IFERROR(VALUE(SUBSTITUTE('Raw Data'!F10,",","")),"")) -> 24963 | G14: =IF(ISNUMBER('Raw Data'!G10),'Raw Data'!G10,IFERROR(VALUE(SUBSTITUTE('Raw Data'!G10,",","")),"")) -> 78 | H14: =IF(ISNUMBER('Raw Data'!H10),'Raw Data'!H10,IFERROR(VALUE(SUBSTITUTE('Raw Data'!H10,",","")),"")) -> 77927 | I14: =IF(ISNUMBER('Raw Data'!I10),'Raw Data'!I10,IFERROR(VALUE(SUBSTITUTE('Raw Data'!I10,",","")),"")) -> 344 | J14: =IF(AND(ISNUMBER(tblClean[[#This Row],[Start Time]]),ISNUMBER(tblClean[[#This Row],[End Time]])),ROUND(MOD(tblClean[[#This Row],[End Time]]-tblClean[[#This Row],[Start Time]],1)*24,2),"") -> 2.5 | K14: =IF(AND(ISNUMBER(tblClean[[#This Row],[Duration Hours]]),ISNUMBER(tblClean[[#This Row],[Attributed GMV PHP]])),IF(tblClean[[#This Row],[Duration Hours]]>0,tblClean[[#This Row],[Attributed GMV PHP]]/tblClean[[#This Row],[Duration Hours]],""),"") -> 9985.2 | L14: =IF(ISNUMBER(tblClean[[#This Row],[Date]]),DATE(YEAR(tblClean[[#This Row],[Date]]),MONTH(tblClean[[#This Row],[Date]]),1),"") -> 45809 | M14: =IF(ISNUMBER(tblClean[[#This Row],[Date]]),tblClean[[#This Row],[Date]]-WEEKDAY(tblClean[[#This Row],[Date]],2)+1,"") -> 45810 | N14: =IF(ISNUMBER(tblClean[[#This Row],[Week Start]]),(tblClean[[#This Row],[Week Start]]-MIN(tblClean[Week Start]))/7+1,"") -> 1 | O14: =IF(ISNUMBER(tblClean[[#This Row],[Date]]),CHOOSE(WEEKDAY(tblClean[[#This Row],[Date]],2),"Mon","Tue","Wed","Thu","Fri","Sat","Sun"),"") -> Tue | P14: =IF(ISNUMBER(tblClean[[#This Row],[Date]]),IF(WEEKDAY(tblClean[[#This Row],[Date]],2)>=6,"Weekend","Weekday"),"") -> Weekday | Q14: =IF(ISNUMBER(tblClean[[#This Row],[Start Time]]),IF(tblClean[[#This Row],[Start Time]]<TIME(6,0,0),"Late Night",IF(tblClean[[#This Row],[Start Time]]<TIME(12,0,0),"Morning",IF(tblClean[[#This Row],[Start Time]]<TIME(16,0,0),"Afternoon",IF(tblClean[[#This Row],[Start Time]]<TIME(19,0,0),"Early Evening",IF(tblClean[[#This Row],[Start Time]]<TIME(22,0,0),"Prime Time","Late Night"))))),"") -> Early Evening | R14: =IF(ISNUMBER(tblClean[[#This Row],[Duration Hours]]),IF(tblClean[[#This Row],[Duration Hours]]<2,"Short (under 2h)",IF(tblClean[[#This Row],[Duration Hours]]<3,"Standard (2h to under 3h)","Long (3h or more)")),"") -> Standard (2h to under 3h) | S14: =IF(OR(NOT(ISNUMBER(tblClean[[#This Row],[Date]])),NOT(ISNUMBER(tblClean[[#This Row],[Start Time]])),NOT(ISNUMBER(tblClean[[#This Row],[End Time]])),NOT(ISNUMBER(tblClean[[#This Row],[Attributed GMV PHP]])),NOT(ISNUMBER(tblClean[[#This Row],[Items Sold]])),NOT(ISNUMBER(tblClean[[#This Row],[Livestream Views]])),NOT(ISNUMBER(tblClean[[#This Row],[New Followers]])),tblClean[[#This Row],[Host Name]]="",tblClean[[#This Row],[Session ID]]=""),1,0) -> 0 | T14: =IF(COUNTIF(tblClean[Session ID],tblClean[[#This Row],[Session ID]])>1,1,0) -> 0 | U14: =IF(OR(N(tblClean[[#This Row],[Attributed GMV PHP]])<0,N(tblClean[[#This Row],[Items Sold]])<0,N(tblClean[[#This Row],[Livestream Views]])<0,N(tblClean[[#This Row],[New Followers]])<0),1,0) -> 0 | V14: =IF(ISNUMBER(tblClean[[#This Row],[Duration Hours]]),IF(OR(tblClean[[#This Row],[Duration Hours]]<=0,tblClean[[#This Row],[Duration Hours]]>12),1,0),1) -> 0 | W14: =IF(COUNTIF(HostRoster,tblClean[[#This Row],[Host Name]])=0,1,0) -> 0 | X14: =IF(tblClean[[#This Row],[Missing Flag]]+tblClean[[#This Row],[Duplicate Flag]]+tblClean[[#This Row],[Negative Flag]]+tblClean[[#This Row],[Duration Flag]]+tblClean[[#This Row],[Host Flag]]=0,1,0) -> 1 | Z14: Master list (input). Named range: HostRoster
A15: =TRIM('Raw Data'!A11) -> LS-0007 | B15: =IF(ISNUMBER('Raw Data'!B11),INT('Raw Data'!B11),IFERROR(DATEVALUE('Raw Data'!B11),"")) -> 45811 | C15: =PROPER(TRIM('Raw Data'!C11)) -> Aira Valdez | D15: =IF(ISNUMBER('Raw Data'!D11),MOD('Raw Data'!D11,1),IFERROR(TIMEVALUE('Raw Data'!D11),"")) -> 0.79166667 | E15: =IF(ISNUMBER('Raw Data'!E11),MOD('Raw Data'!E11,1),IFERROR(TIMEVALUE('Raw Data'!E11),"")) -> 0.89583333 | F15: =IF(ISNUMBER('Raw Data'!F11),'Raw Data'!F11,IFERROR(VALUE(SUBSTITUTE('Raw Data'!F11,",","")),"")) -> 82257 | G15: =IF(ISNUMBER('Raw Data'!G11),'Raw Data'!G11,IFERROR(VALUE(SUBSTITUTE('Raw Data'!G11,",","")),"")) -> 243 | H15: =IF(ISNUMBER('Raw Data'!H11),'Raw Data'!H11,IFERROR(VALUE(SUBSTITUTE('Raw Data'!H11,",","")),"")) -> 216966 | I15: =IF(ISNUMBER('Raw Data'!I11),'Raw Data'!I11,IFERROR(VALUE(SUBSTITUTE('Raw Data'!I11,",","")),"")) -> 1728 | J15: =IF(AND(ISNUMBER(tblClean[[#This Row],[Start Time]]),ISNUMBER(tblClean[[#This Row],[End Time]])),ROUND(MOD(tblClean[[#This Row],[End Time]]-tblClean[[#This Row],[Start Time]],1)*24,2),"") -> 2.5 | K15: =IF(AND(ISNUMBER(tblClean[[#This Row],[Duration Hours]]),ISNUMBER(tblClean[[#This Row],[Attributed GMV PHP]])),IF(tblClean[[#This Row],[Duration Hours]]>0,tblClean[[#This Row],[Attributed GMV PHP]]/tblClean[[#This Row],[Duration Hours]],""),"") -> 32902.8 | L15: =IF(ISNUMBER(tblClean[[#This Row],[Date]]),DATE(YEAR(tblClean[[#This Row],[Date]]),MONTH(tblClean[[#This Row],[Date]]),1),"") -> 45809 | M15: =IF(ISNUMBER(tblClean[[#This Row],[Date]]),tblClean[[#This Row],[Date]]-WEEKDAY(tblClean[[#This Row],[Date]],2)+1,"") -> 45810 | N15: =IF(ISNUMBER(tblClean[[#This Row],[Week Start]]),(tblClean[[#This Row],[Week Start]]-MIN(tblClean[Week Start]))/7+1,"") -> 1 | O15: =IF(ISNUMBER(tblClean[[#This Row],[Date]]),CHOOSE(WEEKDAY(tblClean[[#This Row],[Date]],2),"Mon","Tue","Wed","Thu","Fri","Sat","Sun"),"") -> Tue | P15: =IF(ISNUMBER(tblClean[[#This Row],[Date]]),IF(WEEKDAY(tblClean[[#This Row],[Date]],2)>=6,"Weekend","Weekday"),"") -> Weekday | Q15: =IF(ISNUMBER(tblClean[[#This Row],[Start Time]]),IF(tblClean[[#This Row],[Start Time]]<TIME(6,0,0),"Late Night",IF(tblClean[[#This Row],[Start Time]]<TIME(12,0,0),"Morning",IF(tblClean[[#This Row],[Start Time]]<TIME(16,0,0),"Afternoon",IF(tblClean[[#This Row],[Start Time]]<TIME(19,0,0),"Early Evening",IF(tblClean[[#This Row],[Start Time]]<TIME(22,0,0),"Prime Time","Late Night"))))),"") -> Prime Time | R15: =IF(ISNUMBER(tblClean[[#This Row],[Duration Hours]]),IF(tblClean[[#This Row],[Duration Hours]]<2,"Short (under 2h)",IF(tblClean[[#This Row],[Duration Hours]]<3,"Standard (2h to under 3h)","Long (3h or more)")),"") -> Standard (2h to under 3h) | S15: =IF(OR(NOT(ISNUMBER(tblClean[[#This Row],[Date]])),NOT(ISNUMBER(tblClean[[#This Row],[Start Time]])),NOT(ISNUMBER(tblClean[[#This Row],[End Time]])),NOT(ISNUMBER(tblClean[[#This Row],[Attributed GMV PHP]])),NOT(ISNUMBER(tblClean[[#This Row],[Items Sold]])),NOT(ISNUMBER(tblClean[[#This Row],[Livestream Views]])),NOT(ISNUMBER(tblClean[[#This Row],[New Followers]])),tblClean[[#This Row],[Host Name]]="",tblClean[[#This Row],[Session ID]]=""),1,0) -> 0 | T15: =IF(COUNTIF(tblClean[Session ID],tblClean[[#This Row],[Session ID]])>1,1,0) -> 0 | U15: =IF(OR(N(tblClean[[#This Row],[Attributed GMV PHP]])<0,N(tblClean[[#This Row],[Items Sold]])<0,N(tblClean[[#This Row],[Livestream Views]])<0,N(tblClean[[#This Row],[New Followers]])<0),1,0) -> 0 | V15: =IF(ISNUMBER(tblClean[[#This Row],[Duration Hours]]),IF(OR(tblClean[[#This Row],[Duration Hours]]<=0,tblClean[[#This Row],[Duration Hours]]>12),1,0),1) -> 0 | W15: =IF(COUNTIF(HostRoster,tblClean[[#This Row],[Host Name]])=0,1,0) -> 0 | X15: =IF(tblClean[[#This Row],[Missing Flag]]+tblClean[[#This Row],[Duplicate Flag]]+tblClean[[#This Row],[Negative Flag]]+tblClean[[#This Row],[Duration Flag]]+tblClean[[#This Row],[Host Flag]]=0,1,0) -> 1
A16: =TRIM('Raw Data'!A12) -> LS-0008 | B16: =IF(ISNUMBER('Raw Data'!B12),INT('Raw Data'!B12),IFERROR(DATEVALUE('Raw Data'!B12),"")) -> 45811 | C16: =PROPER(TRIM('Raw Data'!C12)) -> Aira Valdez | D16: =IF(ISNUMBER('Raw Data'!D12),MOD('Raw Data'!D12,1),IFERROR(TIMEVALUE('Raw Data'!D12),"")) -> 0.91666667 | E16: =IF(ISNUMBER('Raw Data'!E12),MOD('Raw Data'!E12,1),IFERROR(TIMEVALUE('Raw Data'!E12),"")) -> 0.020833333 | F16: =IF(ISNUMBER('Raw Data'!F12),'Raw Data'!F12,IFERROR(VALUE(SUBSTITUTE('Raw Data'!F12,",","")),"")) -> 39674 | G16: =IF(ISNUMBER('Raw Data'!G12),'Raw Data'!G12,IFERROR(VALUE(SUBSTITUTE('Raw Data'!G12,",","")),"")) -> 119 | H16: =IF(ISNUMBER('Raw Data'!H12),'Raw Data'!H12,IFERROR(VALUE(SUBSTITUTE('Raw Data'!H12,",","")),"")) -> 102019 | I16: =IF(ISNUMBER('Raw Data'!I12),'Raw Data'!I12,IFERROR(VALUE(SUBSTITUTE('Raw Data'!I12,",","")),"")) -> 825 | J16: =IF(AND(ISNUMBER(tblClean[[#This Row],[Start Time]]),ISNUMBER(tblClean[[#This Row],[End Time]])),ROUND(MOD(tblClean[[#This Row],[End Time]]-tblClean[[#This Row],[Start Time]],1)*24,2),"") -> 2.5 | K16: =IF(AND(ISNUMBER(tblClean[[#This Row],[Duration Hours]]),ISNUMBER(tblClean[[#This Row],[Attributed GMV PHP]])),IF(tblClean[[#This Row],[Duration Hours]]>0,tblClean[[#This Row],[Attributed GMV PHP]]/tblClean[[#This Row],[Duration Hours]],""),"") -> 15869.6 | L16: =IF(ISNUMBER(tblClean[[#This Row],[Date]]),DATE(YEAR(tblClean[[#This Row],[Date]]),MONTH(tblClean[[#This Row],[Date]]),1),"") -> 45809 | M16: =IF(ISNUMBER(tblClean[[#This Row],[Date]]),tblClean[[#This Row],[Date]]-WEEKDAY(tblClean[[#This Row],[Date]],2)+1,"") -> 45810 | N16: =IF(ISNUMBER(tblClean[[#This Row],[Week Start]]),(tblClean[[#This Row],[Week Start]]-MIN(tblClean[Week Start]))/7+1,"") -> 1 | O16: =IF(ISNUMBER(tblClean[[#This Row],[Date]]),CHOOSE(WEEKDAY(tblClean[[#This Row],[Date]],2),"Mon","Tue","Wed","Thu","Fri","Sat","Sun"),"") -> Tue | P16: =IF(ISNUMBER(tblClean[[#This Row],[Date]]),IF(WEEKDAY(tblClean[[#This Row],[Date]],2)>=6,"Weekend","Weekday"),"") -> Weekday | Q16: =IF(ISNUMBER(tblClean[[#This Row],[Start Time]]),IF(tblClean[[#This Row],[Start Time]]<TIME(6,0,0),"Late Night",IF(tblClean[[#This Row],[Start Time]]<TIME(12,0,0),"Morning",IF(tblClean[[#This Row],[Start Time]]<TIME(16,0,0),"Afternoon",IF(tblClean[[#This Row],[Start Time]]<TIME(19,0,0),"Early Evening",IF(tblClean[[#This Row],[Start Time]]<TIME(22,0,0),"Prime Time","Late Night"))))),"") -> Late Night | R16: =IF(ISNUMBER(tblClean[[#This Row],[Duration Hours]]),IF(tblClean[[#This Row],[Duration Hours]]<2,"Short (under 2h)",IF(tblClean[[#This Row],[Duration Hours]]<3,"Standard (2h to under 3h)","Long (3h or more)")),"") -> Standard (2h to under 3h) | S16: =IF(OR(NOT(ISNUMBER(tblClean[[#This Row],[Date]])),NOT(ISNUMBER(tblClean[[#This Row],[Start Time]])),NOT(ISNUMBER(tblClean[[#This Row],[End Time]])),NOT(ISNUMBER(tblClean[[#This Row],[Attributed GMV PHP]])),NOT(ISNUMBER(tblClean[[#This Row],[Items Sold]])),NOT(ISNUMBER(tblClean[[#This Row],[Livestream Views]])),NOT(ISNUMBER(tblClean[[#This Row],[New Followers]])),tblClean[[#This Row],[Host Name]]="",tblClean[[#This Row],[Session ID]]=""),1,0) -> 0 | T16: =IF(COUNTIF(tblClean[Session ID],tblClean[[#This Row],[Session ID]])>1,1,0) -> 0 | U16: =IF(OR(N(tblClean[[#This Row],[Attributed GMV PHP]])<0,N(tblClean[[#This Row],[Items Sold]])<0,N(tblClean[[#This Row],[Livestream Views]])<0,N(tblClean[[#This Row],[New Followers]])<0),1,0) -> 0 | V16: =IF(ISNUMBER(tblClean[[#This Row],[Duration Hours]]),IF(OR(tblClean[[#This Row],[Duration Hours]]<=0,tblClean[[#This Row],[Duration Hours]]>12),1,0),1) -> 0 | W16: =IF(COUNTIF(HostRoster,tblClean[[#This Row],[Host Name]])=0,1,0) -> 0 | X16: =IF(tblClean[[#This Row],[Missing Flag]]+tblClean[[#This Row],[Duplicate Flag]]+tblClean[[#This Row],[Negative Flag]]+tblClean[[#This Row],[Duration Flag]]+tblClean[[#This Row],[Host Flag]]=0,1,0) -> 1
A17: =TRIM('Raw Data'!A13) -> LS-0009 | B17: =IF(ISNUMBER('Raw Data'!B13),INT('Raw Data'!B13),IFERROR(DATEVALUE('Raw Data'!B13),"")) -> 45812 | C17: =PROPER(TRIM('Raw Data'!C13)) -> Carlo Mendoza | D17: =IF(ISNUMBER('Raw Data'!D13),MOD('Raw Data'!D13,1),IFERROR(TIMEVALUE('Raw Data'!D13),"")) -> 0.66666667 | E17: =IF(ISNUMBER('Raw Data'!E13),MOD('Raw Data'!E13,1),IFERROR(TIMEVALUE('Raw Data'!E13),"")) -> 0.79166667 | F17: =IF(ISNUMBER('Raw Data'!F13),'Raw Data'!F13,IFERROR(VALUE(SUBSTITUTE('Raw Data'!F13,",","")),"")) -> 25112 | G17: =IF(ISNUMBER('Raw Data'!G13),'Raw Data'!G13,IFERROR(VALUE(SUBSTITUTE('Raw Data'!G13,",","")),"")) -> 73 | H17: =IF(ISNUMBER('Raw Data'!H13),'Raw Data'!H13,IFERROR(VALUE(SUBSTITUTE('Raw Data'!H13,",","")),"")) -> 77728 | I17: =IF(ISNUMBER('Raw Data'!I13),'Raw Data'!I13,IFERROR(VALUE(SUBSTITUTE('Raw Data'!I13,",","")),"")) -> 552 | J17: =IF(AND(ISNUMBER(tblClean[[#This Row],[Start Time]]),ISNUMBER(tblClean[[#This Row],[End Time]])),ROUND(MOD(tblClean[[#This Row],[End Time]]-tblClean[[#This Row],[Start Time]],1)*24,2),"") -> 3 | K17: =IF(AND(ISNUMBER(tblClean[[#This Row],[Duration Hours]]),ISNUMBER(tblClean[[#This Row],[Attributed GMV PHP]])),IF(tblClean[[#This Row],[Duration Hours]]>0,tblClean[[#This Row],[Attributed GMV PHP]]/tblClean[[#This Row],[Duration Hours]],""),"") -> 8370.6667 | L17: =IF(ISNUMBER(tblClean[[#This Row],[Date]]),DATE(YEAR(tblClean[[#This Row],[Date]]),MONTH(tblClean[[#This Row],[Date]]),1),"") -> 45809 | M17: =IF(ISNUMBER(tblClean[[#This Row],[Date]]),tblClean[[#This Row],[Date]]-WEEKDAY(tblClean[[#This Row],[Date]],2)+1,"") -> 45810 | N17: =IF(ISNUMBER(tblClean[[#This Row],[Week Start]]),(tblClean[[#This Row],[Week Start]]-MIN(tblClean[Week Start]))/7+1,"") -> 1 | O17: =IF(ISNUMBER(tblClean[[#This Row],[Date]]),CHOOSE(WEEKDAY(tblClean[[#This Row],[Date]],2),"Mon","Tue","Wed","Thu","Fri","Sat","Sun"),"") -> Wed | P17: =IF(ISNUMBER(tblClean[[#This Row],[Date]]),IF(WEEKDAY(tblClean[[#This Row],[Date]],2)>=6,"Weekend","Weekday"),"") -> Weekday | Q17: =IF(ISNUMBER(tblClean[[#This Row],[Start Time]]),IF(tblClean[[#This Row],[Start Time]]<TIME(6,0,0),"Late Night",IF(tblClean[[#This Row],[Start Time]]<TIME(12,0,0),"Morning",IF(tblClean[[#This Row],[Start Time]]<TIME(16,0,0),"Afternoon",IF(tblClean[[#This Row],[Start Time]]<TIME(19,0,0),"Early Evening",IF(tblClean[[#This Row],[Start Time]]<TIME(22,0,0),"Prime Time","Late Night"))))),"") -> Early Evening | R17: =IF(ISNUMBER(tblClean[[#This Row],[Duration Hours]]),IF(tblClean[[#This Row],[Duration Hours]]<2,"Short (under 2h)",IF(tblClean[[#This Row],[Duration Hours]]<3,"Standard (2h to under 3h)","Long (3h or more)")),"") -> Long (3h or more) | S17: =IF(OR(NOT(ISNUMBER(tblClean[[#This Row],[Date]])),NOT(ISNUMBER(tblClean[[#This Row],[Start Time]])),NOT(ISNUMBER(tblClean[[#This Row],[End Time]])),NOT(ISNUMBER(tblClean[[#This Row],[Attributed GMV PHP]])),NOT(ISNUMBER(tblClean[[#This Row],[Items Sold]])),NOT(ISNUMBER(tblClean[[#This Row],[Livestream Views]])),NOT(ISNUMBER(tblClean[[#This Row],[New Followers]])),tblClean[[#This Row],[Host Name]]="",tblClean[[#This Row],[Session ID]]=""),1,0) -> 0 | T17: =IF(COUNTIF(tblClean[Session ID],tblClean[[#This Row],[Session ID]])>1,1,0) -> 0 | U17: =IF(OR(N(tblClean[[#This Row],[Attributed GMV PHP]])<0,N(tblClean[[#This Row],[Items Sold]])<0,N(tblClean[[#This Row],[Livestream Views]])<0,N(tblClean[[#This Row],[New Followers]])<0),1,0) -> 0 | V17: =IF(ISNUMBER(tblClean[[#This Row],[Duration Hours]]),IF(OR(tblClean[[#This Row],[Duration Hours]]<=0,tblClean[[#This Row],[Duration Hours]]>12),1,0),1) -> 0 | W17: =IF(COUNTIF(HostRoster,tblClean[[#This Row],[Host Name]])=0,1,0) -> 0 | X17: =IF(tblClean[[#This Row],[Missing Flag]]+tblClean[[#This Row],[Duplicate Flag]]+tblClean[[#This Row],[Negative Flag]]+tblClean[[#This Row],[Duration Flag]]+tblClean[[#This Row],[Host Flag]]=0,1,0) -> 1
A18: =TRIM('Raw Data'!A14) -> LS-0010 | B18: =IF(ISNUMBER('Raw Data'!B14),INT('Raw Data'!B14),IFERROR(DATEVALUE('Raw Data'!B14),"")) -> 45812 | C18: =PROPER(TRIM('Raw Data'!C14)) -> Bianca Reyes | D18: =IF(ISNUMBER('Raw Data'!D14),MOD('Raw Data'!D14,1),IFERROR(TIMEVALUE('Raw Data'!D14),"")) -> 0.79166667 | E18: =IF(ISNUMBER('Raw Data'!E14),MOD('Raw Data'!E14,1),IFERROR(TIMEVALUE('Raw Data'!E14),"")) -> 0.89583333 | F18: =IF(ISNUMBER('Raw Data'!F14),'Raw Data'!F14,IFERROR(VALUE(SUBSTITUTE('Raw Data'!F14,",","")),"")) -> 8207 | G18: =IF(ISNUMBER('Raw Data'!G14),'Raw Data'!G14,IFERROR(VALUE(SUBSTITUTE('Raw Data'!G14,",","")),"")) -> 22 | H18: =IF(ISNUMBER('Raw Data'!H14),'Raw Data'!H14,IFERROR(VALUE(SUBSTITUTE('Raw Data'!H14,",","")),"")) -> 27621 | I18: =IF(ISNUMBER('Raw Data'!I14),'Raw Data'!I14,IFERROR(VALUE(SUBSTITUTE('Raw Data'!I14,",","")),"")) -> 298 | J18: =IF(AND(ISNUMBER(tblClean[[#This Row],[Start Time]]),ISNUMBER(tblClean[[#This Row],[End Time]])),ROUND(MOD(tblClean[[#This Row],[End Time]]-tblClean[[#This Row],[Start Time]],1)*24,2),"") -> 2.5 | K18: =IF(AND(ISNUMBER(tblClean[[#This Row],[Duration Hours]]),ISNUMBER(tblClean[[#This Row],[Attributed GMV PHP]])),IF(tblClean[[#This Row],[Duration Hours]]>0,tblClean[[#This Row],[Attributed GMV PHP]]/tblClean[[#This Row],[Duration Hours]],""),"") -> 3282.8 | L18: =IF(ISNUMBER(tblClean[[#This Row],[Date]]),DATE(YEAR(tblClean[[#This Row],[Date]]),MONTH(tblClean[[#This Row],[Date]]),1),"") -> 45809 | M18: =IF(ISNUMBER(tblClean[[#This Row],[Date]]),tblClean[[#This Row],[Date]]-WEEKDAY(tblClean[[#This Row],[Date]],2)+1,"") -> 45810 | N18: =IF(ISNUMBER(tblClean[[#This Row],[Week Start]]),(tblClean[[#This Row],[Week Start]]-MIN(tblClean[Week Start]))/7+1,"") -> 1 | O18: =IF(ISNUMBER(tblClean[[#This Row],[Date]]),CHOOSE(WEEKDAY(tblClean[[#This Row],[Date]],2),"Mon","Tue","Wed","Thu","Fri","Sat","Sun"),"") -> Wed | P18: =IF(ISNUMBER(tblClean[[#This Row],[Date]]),IF(WEEKDAY(tblClean[[#This Row],[Date]],2)>=6,"Weekend","Weekday"),"") -> Weekday | Q18: =IF(ISNUMBER(tblClean[[#This Row],[Start Time]]),IF(tblClean[[#This Row],[Start Time]]<TIME(6,0,0),"Late Night",IF(tblClean[[#This Row],[Start Time]]<TIME(12,0,0),"Morning",IF(tblClean[[#This Row],[Start Time]]<TIME(16,0,0),"Afternoon",IF(tblClean[[#This Row],[Start Time]]<TIME(19,0,0),"Early Evening",IF(tblClean[[#This Row],[Start Time]]<TIME(22,0,0),"Prime Time","Late Night"))))),"") -> Prime Time | R18: =IF(ISNUMBER(tblClean[[#This Row],[Duration Hours]]),IF(tblClean[[#This Row],[Duration Hours]]<2,"Short (under 2h)",IF(tblClean[[#This Row],[Duration Hours]]<3,"Standard (2h to under 3h)","Long (3h or more)")),"") -> Standard (2h to under 3h) | S18: =IF(OR(NOT(ISNUMBER(tblClean[[#This Row],[Date]])),NOT(ISNUMBER(tblClean[[#This Row],[Start Time]])),NOT(ISNUMBER(tblClean[[#This Row],[End Time]])),NOT(ISNUMBER(tblClean[[#This Row],[Attributed GMV PHP]])),NOT(ISNUMBER(tblClean[[#This Row],[Items Sold]])),NOT(ISNUMBER(tblClean[[#This Row],[Livestream Views]])),NOT(ISNUMBER(tblClean[[#This Row],[New Followers]])),tblClean[[#This Row],[Host Name]]="",tblClean[[#This Row],[Session ID]]=""),1,0) -> 0 | T18: =IF(COUNTIF(tblClean[Session ID],tblClean[[#This Row],[Session ID]])>1,1,0) -> 0 | U18: =IF(OR(N(tblClean[[#This Row],[Attributed GMV PHP]])<0,N(tblClean[[#This Row],[Items Sold]])<0,N(tblClean[[#This Row],[Livestream Views]])<0,N(tblClean[[#This Row],[New Followers]])<0),1,0) -> 0 | V18: =IF(ISNUMBER(tblClean[[#This Row],[Duration Hours]]),IF(OR(tblClean[[#This Row],[Duration Hours]]<=0,tblClean[[#This Row],[Duration Hours]]>12),1,0),1) -> 0 | W18: =IF(COUNTIF(HostRoster,tblClean[[#This Row],[Host Name]])=0,1,0) -> 0 | X18: =IF(tblClean[[#This Row],[Missing Flag]]+tblClean[[#This Row],[Duplicate Flag]]+tblClean[[#This Row],[Negative Flag]]+tblClean[[#This Row],[Duration Flag]]+tblClean[[#This Row],[Host Flag]]=0,1,0) -> 1
A19: =TRIM('Raw Data'!A15) -> LS-0011 | B19: =IF(ISNUMBER('Raw Data'!B15),INT('Raw Data'!B15),IFERROR(DATEVALUE('Raw Data'!B15),"")) -> 45812 | C19: =PROPER(TRIM('Raw Data'!C15)) -> Dani Villanueva | D19: =IF(ISNUMBER('Raw Data'!D15),MOD('Raw Data'!D15,1),IFERROR(TIMEVALUE('Raw Data'!D15),"")) -> 0.91666667 | E19: =IF(ISNUMBER('Raw Data'!E15),MOD('Raw Data'!E15,1),IFERROR(TIMEVALUE('Raw Data'!E15),"")) -> 0.041666667 | F19: =IF(ISNUMBER('Raw Data'!F15),'Raw Data'!F15,IFERROR(VALUE(SUBSTITUTE('Raw Data'!F15,",","")),"")) -> 26243 | G19: =IF(ISNUMBER('Raw Data'!G15),'Raw Data'!G15,IFERROR(VALUE(SUBSTITUTE('Raw Data'!G15,",","")),"")) -> 77 | H19: =IF(ISNUMBER('Raw Data'!H15),'Raw Data'!H15,IFERROR(VALUE(SUBSTITUTE('Raw Data'!H15,",","")),"")) -> 58338 | I19: =IF(ISNUMBER('Raw Data'!I15),'Raw Data'!I15,IFERROR(VALUE(SUBSTITUTE('Raw Data'!I15,",","")),"")) -> 332 | J19: =IF(AND(ISNUMBER(tblClean[[#This Row],[Start Time]]),ISNUMBER(tblClean[[#This Row],[End Time]])),ROUND(MOD(tblClean[[#This Row],[End Time]]-tblClean[[#This Row],[Start Time]],1)*24,2),"") -> 3 | K19: =IF(AND(ISNUMBER(tblClean[[#This Row],[Duration Hours]]),ISNUMBER(tblClean[[#This Row],[Attributed GMV PHP]])),IF(tblClean[[#This Row],[Duration Hours]]>0,tblClean[[#This Row],[Attributed GMV PHP]]/tblClean[[#This Row],[Duration Hours]],""),"") -> 8747.6667 | L19: =IF(ISNUMBER(tblClean[[#This Row],[Date]]),DATE(YEAR(tblClean[[#This Row],[Date]]),MONTH(tblClean[[#This Row],[Date]]),1),"") -> 45809 | M19: =IF(ISNUMBER(tblClean[[#This Row],[Date]]),tblClean[[#This Row],[Date]]-WEEKDAY(tblClean[[#This Row],[Date]],2)+1,"") -> 45810 | N19: =IF(ISNUMBER(tblClean[[#This Row],[Week Start]]),(tblClean[[#This Row],[Week Start]]-MIN(tblClean[Week Start]))/7+1,"") -> 1 | O19: =IF(ISNUMBER(tblClean[[#This Row],[Date]]),CHOOSE(WEEKDAY(tblClean[[#This Row],[Date]],2),"Mon","Tue","Wed","Thu","Fri","Sat","Sun"),"") -> Wed | P19: =IF(ISNUMBER(tblClean[[#This Row],[Date]]),IF(WEEKDAY(tblClean[[#This Row],[Date]],2)>=6,"Weekend","Weekday"),"") -> Weekday | Q19: =IF(ISNUMBER(tblClean[[#This Row],[Start Time]]),IF(tblClean[[#This Row],[Start Time]]<TIME(6,0,0),"Late Night",IF(tblClean[[#This Row],[Start Time]]<TIME(12,0,0),"Morning",IF(tblClean[[#This Row],[Start Time]]<TIME(16,0,0),"Afternoon",IF(tblClean[[#This Row],[Start Time]]<TIME(19,0,0),"Early Evening",IF(tblClean[[#This Row],[Start Time]]<TIME(22,0,0),"Prime Time","Late Night"))))),"") -> Late Night | R19: =IF(ISNUMBER(tblClean[[#This Row],[Duration Hours]]),IF(tblClean[[#This Row],[Duration Hours]]<2,"Short (under 2h)",IF(tblClean[[#This Row],[Duration Hours]]<3,"Standard (2h to under 3h)","Long (3h or more)")),"") -> Long (3h or more) | S19: =IF(OR(NOT(ISNUMBER(tblClean[[#This Row],[Date]])),NOT(ISNUMBER(tblClean[[#This Row],[Start Time]])),NOT(ISNUMBER(tblClean[[#This Row],[End Time]])),NOT(ISNUMBER(tblClean[[#This Row],[Attributed GMV PHP]])),NOT(ISNUMBER(tblClean[[#This Row],[Items Sold]])),NOT(ISNUMBER(tblClean[[#This Row],[Livestream Views]])),NOT(ISNUMBER(tblClean[[#This Row],[New Followers]])),tblClean[[#This Row],[Host Name]]="",tblClean[[#This Row],[Session ID]]=""),1,0) -> 0 | T19: =IF(COUNTIF(tblClean[Session ID],tblClean[[#This Row],[Session ID]])>1,1,0) -> 0 | U19: =IF(OR(N(tblClean[[#This Row],[Attributed GMV PHP]])<0,N(tblClean[[#This Row],[Items Sold]])<0,N(tblClean[[#This Row],[Livestream Views]])<0,N(tblClean[[#This Row],[New Followers]])<0),1,0) -> 0 | V19: =IF(ISNUMBER(tblClean[[#This Row],[Duration Hours]]),IF(OR(tblClean[[#This Row],[Duration Hours]]<=0,tblClean[[#This Row],[Duration Hours]]>12),1,0),1) -> 0 | W19: =IF(COUNTIF(HostRoster,tblClean[[#This Row],[Host Name]])=0,1,0) -> 0 | X19: =IF(tblClean[[#This Row],[Missing Flag]]+tblClean[[#This Row],[Duplicate Flag]]+tblClean[[#This Row],[Negative Flag]]+tblClean[[#This Row],[Duration Flag]]+tblClean[[#This Row],[Host Flag]]=0,1,0) -> 1
A20: =TRIM('Raw Data'!A16) -> LS-0012 | B20: =IF(ISNUMBER('Raw Data'!B16),INT('Raw Data'!B16),IFERROR(DATEVALUE('Raw Data'!B16),"")) -> 45813 | C20: =PROPER(TRIM('Raw Data'!C16)) -> Bianca Reyes | D20: =IF(ISNUMBER('Raw Data'!D16),MOD('Raw Data'!D16,1),IFERROR(TIMEVALUE('Raw Data'!D16),"")) -> 0.54166667 | E20: =IF(ISNUMBER('Raw Data'!E16),MOD('Raw Data'!E16,1),IFERROR(TIMEVALUE('Raw Data'!E16),"")) -> 0.625 | F20: =IF(ISNUMBER('Raw Data'!F16),'Raw Data'!F16,IFERROR(VALUE(SUBSTITUTE('Raw Data'!F16,",","")),"")) -> 6069 | G20: =IF(ISNUMBER('Raw Data'!G16),'Raw Data'!G16,IFERROR(VALUE(SUBSTITUTE('Raw Data'!G16,",","")),"")) -> 17 | H20: =IF(ISNUMBER('Raw Data'!H16),'Raw Data'!H16,IFERROR(VALUE(SUBSTITUTE('Raw Data'!H16,",","")),"")) -> 20285 | I20: =IF(ISNUMBER('Raw Data'!I16),'Raw Data'!I16,IFERROR(VALUE(SUBSTITUTE('Raw Data'!I16,",","")),"")) -> 262 | J20: =IF(AND(ISNUMBER(tblClean[[#This Row],[Start Time]]),ISNUMBER(tblClean[[#This Row],[End Time]])),ROUND(MOD(tblClean[[#This Row],[End Time]]-tblClean[[#This Row],[Start Time]],1)*24,2),"") -> 2 | K20: =IF(AND(ISNUMBER(tblClean[[#This Row],[Duration Hours]]),ISNUMBER(tblClean[[#This Row],[Attributed GMV PHP]])),IF(tblClean[[#This Row],[Duration Hours]]>0,tblClean[[#This Row],[Attributed GMV PHP]]/tblClean[[#This Row],[Duration Hours]],""),"") -> 3034.5 | L20: =IF(ISNUMBER(tblClean[[#This Row],[Date]]),DATE(YEAR(tblClean[[#This Row],[Date]]),MONTH(tblClean[[#This Row],[Date]]),1),"") -> 45809 | M20: =IF(ISNUMBER(tblClean[[#This Row],[Date]]),tblClean[[#This Row],[Date]]-WEEKDAY(tblClean[[#This Row],[Date]],2)+1,"") -> 45810 | N20: =IF(ISNUMBER(tblClean[[#This Row],[Week Start]]),(tblClean[[#This Row],[Week Start]]-MIN(tblClean[Week Start]))/7+1,"") -> 1 | O20: =IF(ISNUMBER(tblClean[[#This Row],[Date]]),CHOOSE(WEEKDAY(tblClean[[#This Row],[Date]],2),"Mon","Tue","Wed","Thu","Fri","Sat","Sun"),"") -> Thu | P20: =IF(ISNUMBER(tblClean[[#This Row],[Date]]),IF(WEEKDAY(tblClean[[#This Row],[Date]],2)>=6,"Weekend","Weekday"),"") -> Weekday | Q20: =IF(ISNUMBER(tblClean[[#This Row],[Start Time]]),IF(tblClean[[#This Row],[Start Time]]<TIME(6,0,0),"Late Night",IF(tblClean[[#This Row],[Start Time]]<TIME(12,0,0),"Morning",IF(tblClean[[#This Row],[Start Time]]<TIME(16,0,0),"Afternoon",IF(tblClean[[#This Row],[Start Time]]<TIME(19,0,0),"Early Evening",IF(tblClean[[#This Row],[Start Time]]<TIME(22,0,0),"Prime Time","Late Night"))))),"") -> Afternoon | R20: =IF(ISNUMBER(tblClean[[#This Row],[Duration Hours]]),IF(tblClean[[#This Row],[Duration Hours]]<2,"Short (under 2h)",IF(tblClean[[#This Row],[Duration Hours]]<3,"Standard (2h to under 3h)","Long (3h or more)")),"") -> Standard (2h to under 3h) | S20: =IF(OR(NOT(ISNUMBER(tblClean[[#This Row],[Date]])),NOT(ISNUMBER(tblClean[[#This Row],[Start Time]])),NOT(ISNUMBER(tblClean[[#This Row],[End Time]])),NOT(ISNUMBER(tblClean[[#This Row],[Attributed GMV PHP]])),NOT(ISNUMBER(tblClean[[#This Row],[Items Sold]])),NOT(ISNUMBER(tblClean[[#This Row],[Livestream Views]])),NOT(ISNUMBER(tblClean[[#This Row],[New Followers]])),tblClean[[#This Row],[Host Name]]="",tblClean[[#This Row],[Session ID]]=""),1,0) -> 0 | T20: =IF(COUNTIF(tblClean[Session ID],tblClean[[#This Row],[Session ID]])>1,1,0) -> 0 | U20: =IF(OR(N(tblClean[[#This Row],[Attributed GMV PHP]])<0,N(tblClean[[#This Row],[Items Sold]])<0,N(tblClean[[#This Row],[Livestream Views]])<0,N(tblClean[[#This Row],[New Followers]])<0),1,0) -> 0 | V20: =IF(ISNUMBER(tblClean[[#This Row],[Duration Hours]]),IF(OR(tblClean[[#This Row],[Duration Hours]]<=0,tblClean[[#This Row],[Duration Hours]]>12),1,0),1) -> 0 | W20: =IF(COUNTIF(HostRoster,tblClean[[#This Row],[Host Name]])=0,1,0) -> 0 | X20: =IF(tblClean[[#This Row],[Missing Flag]]+tblClean[[#This Row],[Duplicate Flag]]+tblClean[[#This Row],[Negative Flag]]+tblClean[[#This Row],[Duration Flag]]+tblClean[[#This Row],[Host Flag]]=0,1,0) -> 1
